[32m2025-07-03 00:32:08 +0000[0m - dagster - [34mDEBUG[0m - __ASSET_JOB - ff4555a4-8317-4a32-b810-92a613b72bbb - 524290 - LOGS_CAPTURED - Started capturing logs in process (pid: 524290).
[32m2025-07-03 00:32:08 +0000[0m - dagster - [34mDEBUG[0m - __ASSET_JOB - ff4555a4-8317-4a32-b810-92a613b72bbb - 524290 - validate - STEP_START - Started execution of step "validate".
[32m2025-07-03 00:32:08 +0000[0m - dagster - [34mDEBUG[0m - __ASSET_JOB - ff4555a4-8317-4a32-b810-92a613b72bbb - validate - Loading file from: /workspaces/data-scientist-at-magenta/dagster_home/storage/tune using PickledObjectFilesystemIOManager...
[32m2025-07-03 00:32:08 +0000[0m - dagster - [34mDEBUG[0m - __ASSET_JOB - ff4555a4-8317-4a32-b810-92a613b72bbb - 524290 - validate - LOADED_INPUT - Loaded input "tune" using input manager "io_manager", from output "result" of step "tune"
[32m2025-07-03 00:32:08 +0000[0m - dagster - [34mDEBUG[0m - __ASSET_JOB - ff4555a4-8317-4a32-b810-92a613b72bbb - 524290 - validate - STEP_INPUT - Got input "tune" of type "Any". (Type check passed).
[32m2025-07-03 00:32:08 +0000[0m - dagster - [34mINFO[0m - __ASSET_JOB - ff4555a4-8317-4a32-b810-92a613b72bbb - validate - Starting model validation process
[32m2025-07-03 00:32:08 +0000[0m - dagster - [34mINFO[0m - __ASSET_JOB - ff4555a4-8317-4a32-b810-92a613b72bbb - validate - Evaluating new model on test set
[32m2025-07-03 00:32:08 +0000[0m - dagster - [34mINFO[0m - __ASSET_JOB - ff4555a4-8317-4a32-b810-92a613b72bbb - validate - New model metrics: F1=0.0000, Accuracy=0.8300, Precision=0.0000, Recall=0.0000
[32m2025-07-03 00:32:08 +0000[0m - dagster - [34mINFO[0m - __ASSET_JOB - ff4555a4-8317-4a32-b810-92a613b72bbb - validate - Evaluating current model on test set
[32m2025-07-03 00:32:08 +0000[0m - dagster - [34mERROR[0m - [31m__ASSET_JOB - ff4555a4-8317-4a32-b810-92a613b72bbb - 524290 - validate - STEP_FAILURE - Execution of step "validate" failed.

dagster._core.errors.DagsterExecutionStepExecutionError: Error occurred while executing op "validate"::

ValueError: X has 50 features, but RandomForestClassifier is expecting 49 features as input.

Stack Trace:
  File "/workspaces/data-scientist-at-magenta/.pixi/envs/ci-validation/lib/python3.12/site-packages/dagster/_core/execution/plan/utils.py", line 56, in op_execution_error_boundary
    yield
  File "/workspaces/data-scientist-at-magenta/.pixi/envs/ci-validation/lib/python3.12/site-packages/dagster/_utils/__init__.py", line 480, in iterate_with_context
    next_output = next(iterator)
                  ^^^^^^^^^^^^^^
  File "/workspaces/data-scientist-at-magenta/.pixi/envs/ci-validation/lib/python3.12/site-packages/dagster/_core/execution/plan/compute_generator.py", line 127, in _coerce_op_compute_fn_to_iterator
    result = invoke_compute_fn(
             ^^^^^^^^^^^^^^^^^^
  File "/workspaces/data-scientist-at-magenta/.pixi/envs/ci-validation/lib/python3.12/site-packages/dagster/_core/execution/plan/compute_generator.py", line 115, in invoke_compute_fn
    return fn(context, **args_to_pass) if context_arg_provided else fn(**args_to_pass)
                                                                    ^^^^^^^^^^^^^^^^^^
  File "/workspaces/data-scientist-at-magenta/src/code_location_interview/code_location_interview/assets/training.py", line 308, in validate
    current_predictions = current_model.predict(X_test)
                          ^^^^^^^^^^^^^^^^^^^^^^^^^^^^^
  File "/workspaces/data-scientist-at-magenta/.pixi/envs/ci-validation/lib/python3.12/site-packages/sklearn/ensemble/_forest.py", line 903, in predict
    proba = self.predict_proba(X)
            ^^^^^^^^^^^^^^^^^^^^^
  File "/workspaces/data-scientist-at-magenta/.pixi/envs/ci-validation/lib/python3.12/site-packages/sklearn/ensemble/_forest.py", line 945, in predict_proba
    X = self._validate_X_predict(X)
        ^^^^^^^^^^^^^^^^^^^^^^^^^^^
  File "/workspaces/data-scientist-at-magenta/.pixi/envs/ci-validation/lib/python3.12/site-packages/sklearn/ensemble/_forest.py", line 637, in _validate_X_predict
    X = validate_data(
        ^^^^^^^^^^^^^^
  File "/workspaces/data-scientist-at-magenta/.pixi/envs/ci-validation/lib/python3.12/site-packages/sklearn/utils/validation.py", line 2975, in validate_data
    _check_n_features(_estimator, X, reset=reset)
  File "/workspaces/data-scientist-at-magenta/.pixi/envs/ci-validation/lib/python3.12/site-packages/sklearn/utils/validation.py", line 2839, in _check_n_features
    raise ValueError(
[0m
