[32m2025-07-02 17:47:53 +0000[0m - dagster - [34mDEBUG[0m - __ASSET_JOB - 21c90a4f-1cce-4874-9c57-0ffb9f006d77 - 25486 - LOGS_CAPTURED - Started capturing logs in process (pid: 25486).
[32m2025-07-02 17:47:53 +0000[0m - dagster - [34mDEBUG[0m - __ASSET_JOB - 21c90a4f-1cce-4874-9c57-0ffb9f006d77 - 25486 - labels_ingestion - STEP_START - Started execution of step "labels_ingestion".
[32m2025-07-02 17:47:53 +0000[0m - dagster - [34mDEBUG[0m - __ASSET_JOB - 21c90a4f-1cce-4874-9c57-0ffb9f006d77 - labels_ingestion - Loading file from: /workspaces/data-scientist-at-magenta/dagster_home/storage/core_data using PickledObjectFilesystemIOManager...
[32m2025-07-02 17:47:53 +0000[0m - dagster - [34mDEBUG[0m - __ASSET_JOB - 21c90a4f-1cce-4874-9c57-0ffb9f006d77 - 25486 - labels_ingestion - LOADED_INPUT - Loaded input "core_data" using input manager "io_manager", from output "core_data" of step "core_data"
[32m2025-07-02 17:47:53 +0000[0m - dagster - [34mDEBUG[0m - __ASSET_JOB - 21c90a4f-1cce-4874-9c57-0ffb9f006d77 - 25486 - labels_ingestion - STEP_INPUT - Got input "core_data" of type "Any". (Type check passed).
[32m2025-07-02 17:47:53 +0000[0m - dagster - [34mINFO[0m - __ASSET_JOB - 21c90a4f-1cce-4874-9c57-0ffb9f006d77 - labels_ingestion - Starting labels ingestion
[32m2025-07-02 17:47:53 +0000[0m - dagster - [34mINFO[0m - __ASSET_JOB - 21c90a4f-1cce-4874-9c57-0ffb9f006d77 - labels_ingestion - Storing labels
[32m2025-07-02 17:47:53 +0000[0m - dagster - [34mERROR[0m - [31m__ASSET_JOB - 21c90a4f-1cce-4874-9c57-0ffb9f006d77 - 25486 - labels_ingestion - STEP_FAILURE - Execution of step "labels_ingestion" failed.

dagster._core.errors.DagsterExecutionStepExecutionError: Error occurred while executing op "labels_ingestion"::

duckdb.duckdb.BinderException: Binder Error: table raw_labels has 3 columns but 2 values were supplied

Stack Trace:
  File "/workspaces/data-scientist-at-magenta/.pixi/envs/ci-validation/lib/python3.12/site-packages/dagster/_core/execution/plan/utils.py", line 56, in op_execution_error_boundary
    yield
  File "/workspaces/data-scientist-at-magenta/.pixi/envs/ci-validation/lib/python3.12/site-packages/dagster/_utils/__init__.py", line 480, in iterate_with_context
    next_output = next(iterator)
                  ^^^^^^^^^^^^^^
  File "/workspaces/data-scientist-at-magenta/.pixi/envs/ci-validation/lib/python3.12/site-packages/dagster/_core/execution/plan/compute_generator.py", line 127, in _coerce_op_compute_fn_to_iterator
    result = invoke_compute_fn(
             ^^^^^^^^^^^^^^^^^^
  File "/workspaces/data-scientist-at-magenta/.pixi/envs/ci-validation/lib/python3.12/site-packages/dagster/_core/execution/plan/compute_generator.py", line 115, in invoke_compute_fn
    return fn(context, **args_to_pass) if context_arg_provided else fn(**args_to_pass)
                                                                    ^^^^^^^^^^^^^^^^^^
  File "/workspaces/data-scientist-at-magenta/src/code_location_interview/code_location_interview/assets/data_ingestion.py", line 165, in labels_ingestion
    conn.execute("INSERT OR REPLACE INTO raw_labels SELECT * FROM labels_df")
[0m
