[32m2025-07-02 23:12:21 +0000[0m - dagster - [34mDEBUG[0m - __ASSET_JOB - 0fc738e6-8979-4b67-ab1d-90969dcd1102 - 269681 - LOGS_CAPTURED - Started capturing logs in process (pid: 269681).
[32m2025-07-02 23:12:21 +0000[0m - dagster - [34mDEBUG[0m - __ASSET_JOB - 0fc738e6-8979-4b67-ab1d-90969dcd1102 - 269681 - current_model - STEP_START - Started execution of step "current_model".
[32m2025-07-02 23:12:21 +0000[0m - dagster - [34mINFO[0m - __ASSET_JOB - 0fc738e6-8979-4b67-ab1d-90969dcd1102 - current_model - Loading current deployed model from model registry
[32m2025-07-02 23:12:21 +0000[0m - dagster - [34mERROR[0m - [31m__ASSET_JOB - 0fc738e6-8979-4b67-ab1d-90969dcd1102 - current_model - model_registry table does not exist in database![0m
[32m2025-07-02 23:12:21 +0000[0m - dagster - [34mERROR[0m - [31m__ASSET_JOB - 0fc738e6-8979-4b67-ab1d-90969dcd1102 - current_model - Available tables: [][0m
[32m2025-07-02 23:12:21 +0000[0m - dagster - [34mERROR[0m - [31m__ASSET_JOB - 0fc738e6-8979-4b67-ab1d-90969dcd1102 - current_model - Error checking database tables: model_registry table not found. Please run the database initialization script: python init_database.py[0m
[32m2025-07-02 23:12:21 +0000[0m - dagster - [34mERROR[0m - [31m__ASSET_JOB - 0fc738e6-8979-4b67-ab1d-90969dcd1102 - 269681 - current_model - STEP_FAILURE - Execution of step "current_model" failed.

dagster._core.errors.DagsterExecutionStepExecutionError: Error occurred while executing op "current_model"::

ValueError: model_registry table not found. Please run the database initialization script: python init_database.py

Stack Trace:
  File "/workspaces/data-scientist-at-magenta/.pixi/envs/ci-validation/lib/python3.12/site-packages/dagster/_core/execution/plan/utils.py", line 56, in op_execution_error_boundary
    yield
  File "/workspaces/data-scientist-at-magenta/.pixi/envs/ci-validation/lib/python3.12/site-packages/dagster/_utils/__init__.py", line 480, in iterate_with_context
    next_output = next(iterator)
                  ^^^^^^^^^^^^^^
  File "/workspaces/data-scientist-at-magenta/.pixi/envs/ci-validation/lib/python3.12/site-packages/dagster/_core/execution/plan/compute_generator.py", line 127, in _coerce_op_compute_fn_to_iterator
    result = invoke_compute_fn(
             ^^^^^^^^^^^^^^^^^^
  File "/workspaces/data-scientist-at-magenta/.pixi/envs/ci-validation/lib/python3.12/site-packages/dagster/_core/execution/plan/compute_generator.py", line 115, in invoke_compute_fn
    return fn(context, **args_to_pass) if context_arg_provided else fn(**args_to_pass)
                                                                    ^^^^^^^^^^^^^^^^^^
  File "/workspaces/data-scientist-at-magenta/src/code_location_interview/code_location_interview/assets/predict.py", line 41, in current_model
    raise ValueError(
[0m
